<?xml version="1.0" ?>
<robot name="arm">

  <material name="black">
    <color rgba="0.0 0.0 0.0 1.0"/>
  </material>
  <material name="orange">
    <color rgba="1.0 0.4 0.0 1.0"/>
  </material>

  <link name="body">
    <collision>
      <origin xyz="0 0 0.7" rpy="0 0 0"/>
      <geometry>
        <box size="0.6 0.6 1.4"/>
      </geometry>
    </collision>
    <visual>
      <origin xyz="0 0 0.7" rpy="0 0 0"/>
      <geometry>
        <box size="0.6 0.6 1.4"/>
      </geometry>
      <material name="black"/>
    </visual>
    <inertial>
      <origin xyz="0 0 0.7" rpy="0 0 0"/>
      <mass value="12"/>
      <inertia ixx="2.3" ixy="0.0" ixz="0.0" iyy="2.3" iyz="0.0" izz="0.7"/>
    </inertial>
  </link>

  <joint name="body__right_link1" type="revolute">
    <parent link="body"/>
    <child link="right_link1"/>
    <origin xyz="0.3 0 1.2" rpy="0 0 0"/>
    <axis xyz="1 0 0"/>
    <limit effort="30" lower="-3.14" upper="3.14" velocity="1.571"/>
  </joint>

  <link name="right_link1">
    <collision>
      <origin xyz="0.375 0 1.2" rpy="0 0 0"/>
      <geometry>
        <box size="0.15 0.05 0.05"/>
      </geometry>
    </collision>
    <visual>
      <origin xyz="0.375 0 1.2" rpy="0 0 0"/>
      <geometry>
        <box size="0.15 0.05 0.05"/>
      </geometry>
      <material name="orange"/>
    </visual>
    <inertial>
      <origin xyz="0.375 0 1.2" rpy="0 0 0"/>
      <mass value="1"/>
      <inertia ixx="1.0" ixy="0.0" ixz="0.0" iyy="1.0" iyz="0.0" izz="1.0"/>
    </inertial>
  </link>

  <joint name="right_link1__right_link2" type="revolute">
    <parent link="right_link1"/>
    <child link="right_link2"/>
    <origin xyz="0.45 0 1.2" rpy="0 0 0"/>
    <axis xyz="0 1 0"/>
    <limit effort="30" lower="-3.14" upper="3.14" velocity="1.571"/>
  </joint>

  <link name="right_link2">
    <collision>
      <origin xyz="0.5 0 1.075" rpy="0 0 0"/>
      <geometry>
        <box size="0.05 0.05 0.25"/>
      </geometry>
    </collision>
    <visual>
      <origin xyz="0.5 0 1.075" rpy="0 0 0"/>
      <geometry>
        <box size="0.05 0.05 0.25"/>
      </geometry>
      <material name="black"/>
    </visual>
    <inertial>
      <origin xyz="0.5 0 1.075" rpy="0 0 0"/>
      <mass value="1"/>
      <inertia ixx="1.0" ixy="0.0" ixz="0.0" iyy="1.0" iyz="0.0" izz="1.0"/>
    </inertial>
  </link>

  <joint name="right_link2__right_link3" type="revolute">
    <parent link="right_link2"/>
    <child link="right_link3"/>
    <origin xyz="0.5 0 0.95" rpy="0 0 0"/>
    <axis xyz="0 1 0"/>
    <limit effort="30" lower="-3.14" upper="3.14" velocity="1.571"/>
  </joint>

  <link name="right_link3">
    <collision>
      <origin xyz="0.5 0 0.825" rpy="0 0 0"/>
      <geometry>
        <box size="0.05 0.05 0.25"/>
      </geometry>
    </collision>
    <visual>
      <origin xyz="0.5 0 0.825" rpy="0 0 0"/>
      <geometry>
        <box size="0.05 0.05 0.25"/>
      </geometry>
      <material name="orange"/>
    </visual>
    <inertial>
      <origin xyz="0.5 0 0.825" rpy="0 0 0"/>
      <mass value="1"/>
      <inertia ixx="1.0" ixy="0.0" ixz="0.0" iyy="1.0" iyz="0.0" izz="1.0"/>
    </inertial>
  </link>

  <joint name="right_link3__right_link4" type="revolute">
    <parent link="right_link3"/>
    <child link="right_link4"/>
    <origin xyz="0.5 0 0.7" rpy="0 0 0"/>
    <axis xyz="1 0 0"/>
    <limit effort="30" lower="-3.14" upper="3.14" velocity="1.571"/>
  </joint>

  <link name="right_link4">
    <collision>
      <origin xyz="0.5 0 0.625" rpy="0 0 0"/>
      <geometry>
        <box size="0.05 0.05 0.25"/>
      </geometry>
    </collision>
    <visual>
      <origin xyz="0.5 0 0.625" rpy="0 0 0"/>
      <geometry>
        <box size="0.05 0.05 0.25"/>
      </geometry>
      <material name="black"/>
    </visual>
    <inertial>
      <origin xyz="0.5 0 0.625" rpy="0 0 0"/>
      <mass value="1"/>
      <inertia ixx="1.0" ixy="0.0" ixz="0.0" iyy="1.0" iyz="0.0" izz="1.0"/>
    </inertial>
  </link>


<joint name="body__left_link1" type="revolute">
    <parent link="body"/>
    <child link="left_link1"/>
    <origin xyz="-0.3 0 1.2" rpy="0 0 0"/>
    <axis xyz="1 0 0"/>
    <limit effort="30" lower="-3.14" upper="3.14" velocity="1.571"/>
  </joint>

  <link name="left_link1">
    <collision>
      <origin xyz="-0.375 0 1.2" rpy="0 0 0"/>
      <geometry>
        <box size="0.15 0.05 0.05"/>
      </geometry>
    </collision>
    <visual>
      <origin xyz="-0.375 0 1.2" rpy="0 0 0"/>
      <geometry>
        <box size="0.15 0.05 0.05"/>
      </geometry>
      <material name="orange"/>
    </visual>
    <inertial>
      <origin xyz="-0.375 0 1.2" rpy="0 0 0"/>
      <mass value="1"/>
      <inertia ixx="1.0" ixy="0.0" ixz="0.0" iyy="1.0" iyz="0.0" izz="1.0"/>
    </inertial>
  </link>

  <joint name="left_link1__left_link2" type="revolute">
    <parent link="left_link1"/>
    <child link="left_link2"/>
    <origin xyz="-0.45 0 1.2" rpy="0 0 0"/>
    <axis xyz="0 1 0"/>
    <limit effort="30" lower="-3.14" upper="3.14" velocity="1.571"/>
  </joint>

  <link name="left_link2">
    <collision>
      <origin xyz="-0.5 0 1.075" rpy="0 0 0"/>
      <geometry>
        <box size="0.05 0.05 0.25"/>
      </geometry>
    </collision>
    <visual>
      <origin xyz="-0.5 0 1.075" rpy="0 0 0"/>
      <geometry>
        <box size="0.05 0.05 0.25"/>
      </geometry>
      <material name="black"/>
    </visual>
    <inertial>
      <origin xyz="-0.5 0 1.075" rpy="0 0 0"/>
      <mass value="1"/>
      <inertia ixx="1.0" ixy="0.0" ixz="0.0" iyy="1.0" iyz="0.0" izz="1.0"/>
    </inertial>
  </link>

  <joint name="left_link2__left_link3" type="revolute">
    <parent link="left_link2"/>
    <child link="left_link3"/>
    <origin xyz="-0.5 0 0.95" rpy="0 0 0"/>
    <axis xyz="0 1 0"/>
    <limit effort="30" lower="-3.14" upper="3.14" velocity="1.571"/>
  </joint>

  <link name="left_link3">
    <collision>
      <origin xyz="-0.5 0 0.825" rpy="0 0 0"/>
      <geometry>
        <box size="0.05 0.05 0.25"/>
      </geometry>
    </collision>
    <visual>
      <origin xyz="-0.5 0 0.825" rpy="0 0 0"/>
      <geometry>
        <box size="0.05 0.05 0.25"/>
      </geometry>
      <material name="orange"/>
    </visual>
    <inertial>
      <origin xyz="-0.5 0 0.825" rpy="0 0 0"/>
      <mass value="1"/>
      <inertia ixx="1.0" ixy="0.0" ixz="0.0" iyy="1.0" iyz="0.0" izz="1.0"/>
    </inertial>
  </link>

  <joint name="left_link3__left_link4" type="revolute">
    <parent link="left_link3"/>
    <child link="left_link4"/>
    <origin xyz="-0.5 0 0.7" rpy="0 0 0"/>
    <axis xyz="1 0 0"/>
    <limit effort="30" lower="-3.14" upper="3.14" velocity="1.571"/>
  </joint>

  <link name="left_link4">
    <collision>
      <origin xyz="-0.5 0 0.625" rpy="0 0 0"/>
      <geometry>
        <box size="0.05 0.05 0.25"/>
      </geometry>
    </collision>
    <visual>
      <origin xyz="-0.5 0 0.625" rpy="0 0 0"/>
      <geometry>
        <box size="0.05 0.05 0.25"/>
      </geometry>
      <material name="black"/>
    </visual>
    <inertial>
      <origin xyz="-0.5 0 0.625" rpy="0 0 0"/>
      <mass value="1"/>
      <inertia ixx="1.0" ixy="0.0" ixz="0.0" iyy="1.0" iyz="0.0" izz="1.0"/>
    </inertial>
  </link>
</robot>
